Workbook
Name Кал_Даты: Календарь!$A$2:$A$366
Name Кал_Месяц: Календарь!$B$2:$B$366
Name Кал_Раб: Календарь!$D$2:$D$366
Name Нед_Начало: 'Рабочие дни'!$B$20:$B$72
Name Нед_Конец: 'Рабочие дни'!$C$20:$C$72
Name Нед_Раб: 'Рабочие дни'!$E$20:$E$72
Name Мес_Раб: 'Рабочие дни'!$B$5:$B$16

Sheet План на фин. неделю
A1: ПЛАН НА ФИНАНСОВУЮ НЕДЕЛЮ (четверг — среда)
A2: Сотрудник находит свою фамилию и активную неделю — это его план на неделю.
A4: Активная дата: | B4: 46317 | C4: ← поставьте любую дату (хоть =СЕГОДНЯ()). Активная неделя подсветится в таблице и появится справа.
A6: ТАБЛИЦА 1. Все недели года | BD6: ТАБЛИЦА 2. Активная неделя
A7: № недели | B7: 1 | C7: 2 | D7: 3 | E7: 4 | F7: 5 | G7: 6 | H7: 7 | I7: 8 | J7: 9 | K7: 10 | L7: 11 | M7: 12 | N7: 13 | O7: 14 | P7: 15 | Q7: 16 | R7: 17 | S7: 18 | T7: 19 | U7: 20 | V7: 21 | W7: 22 | X7: 23 | Y7: 24 | Z7: 25 | AA7: 26 | AB7: 27 | AC7: 28 | AD7: 29 | AE7: 30 | AF7: 31 | AG7: 32 | AH7: 33 | AI7: 34 | AJ7: 35 | AK7: 36 | AL7: 37 | AM7: 38 | AN7: 39 | AO7: 40 | AP7: 41 | AQ7: 42 | AR7: 43 | AS7: 44 | AT7: 45 | AU7: 46 | AV7: 47 | AW7: 48 | AX7: 49 | AY7: 50 | AZ7: 51 | BA7: 52 | BB7: 53 | BD7: № активной недели | BE7: Период
A8: Период | B8: 01.01 — 07.01 | C8: 08.01 — 14.01 | D8: 15.01 — 21.01 | E8: 22.01 — 28.01 | F8: 29.01 — 04.02 | G8: 05.02 — 11.02 | H8: 12.02 — 18.02 | I8: 19.02 — 25.02 | J8: 26.02 — 04.03 | K8: 05.03 — 11.03 | L8: 12.03 — 18.03 | M8: 19.03 — 25.03 | N8: 26.03 — 01.04 | O8: 02.04 — 08.04 | P8: 09.04 — 15.04 | Q8: 16.04 — 22.04 | R8: 23.04 — 29.04 | S8: 30.04 — 06.05 | T8: 07.05 — 13.05 | U8: 14.05 — 20.05 | V8: 21.05 — 27.05 | W8: 28.05 — 03.06 | X8: 04.06 — 10.06 | Y8: 11.06 — 17.06 | Z8: 18.06 — 24.06 | AA8: 25.06 — 01.07 | AB8: 02.07 — 08.07 | AC8: 09.07 — 15.07 | AD8: 16.07 — 22.07 | AE8: 23.07 — 29.07 | AF8: 30.07 — 05.08 | AG8: 06.08 — 12.08 | AH8: 13.08 — 19.08 | AI8: 20.08 — 26.08 | AJ8: 27.08 — 02.09 | AK8: 03.09 — 09.09 | AL8: 10.09 — 16.09 | AM8: 17.09 — 23.09 | AN8: 24.09 — 30.09 | AO8: 01.10 — 07.10 | AP8: 08.10 — 14.10 | AQ8: 15.10 — 21.10 | AR8: 22.10 — 28.10 | AS8: 29.10 — 04.11 | AT8: 05.11 — 11.11 | AU8: 12.11 — 18.11 | AV8: 19.11 — 25.11 | AW8: 26.11 — 02.12 | AX8: 03.12 — 09.12 | AY8: 10.12 — 16.12 | AZ8: 17.12 — 23.12 | BA8: 24.12 — 30.12 | BB8: 31.12 — 06.01 | BD8: =IFERROR(MATCH($B$4,Нед_Начало,1),MATCH($B$4,Нед_Конец,1)) | BE8: =TEXT(INDEX(Нед_Начало,$BD$8),"dd.mm.yyyy")&" — "&TEXT(INDEX(Нед_Конец,$BD$8),"dd.mm.yyyy")
A9: Рабочих дней | B9: =INDEX(Нед_Раб,1) | C9: =INDEX(Нед_Раб,2) | D9: =INDEX(Нед_Раб,3) | E9: =INDEX(Нед_Раб,4) | F9: =INDEX(Нед_Раб,5) | G9: =INDEX(Нед_Раб,6) | H9: =INDEX(Нед_Раб,7) | I9: =INDEX(Нед_Раб,8) | J9: =INDEX(Нед_Раб,9) | K9: =INDEX(Нед_Раб,10) | L9: =INDEX(Нед_Раб,11) | M9: =INDEX(Нед_Раб,12) | N9: =INDEX(Нед_Раб,13) | O9: =INDEX(Нед_Раб,14) | P9: =INDEX(Нед_Раб,15) | Q9: =INDEX(Нед_Раб,16) | R9: =INDEX(Нед_Раб,17) | S9: =INDEX(Нед_Раб,18) | T9: =INDEX(Нед_Раб,19) | U9: =INDEX(Нед_Раб,20) | V9: =INDEX(Нед_Раб,21) | W9: =INDEX(Нед_Раб,22) | X9: =INDEX(Нед_Раб,23) | Y9: =INDEX(Нед_Раб,24) | Z9: =INDEX(Нед_Раб,25) | AA9: =INDEX(Нед_Раб,26) | AB9: =INDEX(Нед_Раб,27) | AC9: =INDEX(Нед_Раб,28) | AD9: =INDEX(Нед_Раб,29) | AE9: =INDEX(Нед_Раб,30) | AF9: =INDEX(Нед_Раб,31) | AG9: =INDEX(Нед_Раб,32) | AH9: =INDEX(Нед_Раб,33) | AI9: =INDEX(Нед_Раб,34) | AJ9: =INDEX(Нед_Раб,35) | AK9: =INDEX(Нед_Раб,36) | AL9: =INDEX(Нед_Раб,37) | AM9: =INDEX(Нед_Раб,38) | AN9: =INDEX(Нед_Раб,39) | AO9: =INDEX(Нед_Раб,40) | AP9: =INDEX(Нед_Раб,41) | AQ9: =INDEX(Нед_Раб,42) | AR9: =INDEX(Нед_Раб,43) | AS9: =INDEX(Нед_Раб,44) | AT9: =INDEX(Нед_Раб,45) | AU9: =INDEX(Нед_Раб,46) | AV9: =INDEX(Нед_Раб,47) | AW9: =INDEX(Нед_Раб,48) | AX9: =INDEX(Нед_Раб,49) | AY9: =INDEX(Нед_Раб,50) | AZ9: =INDEX(Нед_Раб,51) | BA9: =INDEX(Нед_Раб,52) | BB9: =INDEX(Нед_Раб,53)
A10: Иванов | B10: ='Расчёт'!D4460 | C10: ='Расчёт'!D4461 | D10: ='Расчёт'!D4462 | E10: ='Расчёт'!D4463 | F10: ='Расчёт'!D4464 | G10: ='Расчёт'!D4465 | H10: ='Расчёт'!D4466 | I10: ='Расчёт'!D4467 | J10: ='Расчёт'!D4468 | K10: ='Расчёт'!D4469 | L10: ='Расчёт'!D4470 | M10: ='Расчёт'!D4471 | N10: ='Расчёт'!D4472 | O10: ='Расчёт'!D4473 | P10: ='Расчёт'!D4474 | Q10: ='Расчёт'!D4475 | R10: ='Расчёт'!D4476 | S10: ='Расчёт'!D4477 | T10: ='Расчёт'!D4478 | U10: ='Расчёт'!D4479 | V10: ='Расчёт'!D4480 | W10: ='Расчёт'!D4481 | X10: ='Расчёт'!D4482 | Y10: ='Расчёт'!D4483 | Z10: ='Расчёт'!D4484 | AA10: ='Расчёт'!D4485 | AB10: ='Расчёт'!D4486 | AC10: ='Расчёт'!D4487 | AD10: ='Расчёт'!D4488 | AE10: ='Расчёт'!D4489 | AF10: ='Расчёт'!D4490 | AG10: ='Расчёт'!D4491 | AH10: ='Расчёт'!D4492 | AI10: ='Расчёт'!D4493 | AJ10: ='Расчёт'!D4494 | AK10: ='Расчёт'!D4495 | AL10: ='Расчёт'!D4496 | AM10: ='Расчёт'!D4497 | AN10: ='Расчёт'!D4498 | AO10: ='Расчёт'!D4499 | AP10: ='Расчёт'!D4500 | AQ10: ='Расчёт'!D4501 | AR10: ='Расчёт'!D4502 | AS10: ='Расчёт'!D4503 | AT10: ='Расчёт'!D4504 | AU10: ='Расчёт'!D4505 | AV10: ='Расчёт'!D4506 | AW10: ='Расчёт'!D4507 | AX10: ='Расчёт'!D4508 | AY10: ='Расчёт'!D4509 | AZ10: ='Расчёт'!D4510 | BA10: ='Расчёт'!D4511 | BB10: ='Расчёт'!D4512 | BD10: Менеджер | BE10: План на активную неделю
A11: Петрова | B11: ='Расчёт'!D4513 | C11: ='Расчёт'!D4514 | D11: ='Расчёт'!D4515 | E11: ='Расчёт'!D4516 | F11: ='Расчёт'!D4517 | G11: ='Расчёт'!D4518 | H11: ='Расчёт'!D4519 | I11: ='Расчёт'!D4520 | J11: ='Расчёт'!D4521 | K11: ='Расчёт'!D4522 | L11: ='Расчёт'!D4523 | M11: ='Расчёт'!D4524 | N11: ='Расчёт'!D4525 | O11: ='Расчёт'!D4526 | P11: ='Расчёт'!D4527 | Q11: ='Расчёт'!D4528 | R11: ='Расчёт'!D4529 | S11: ='Расчёт'!D4530 | T11: ='Расчёт'!D4531 | U11: ='Расчёт'!D4532 | V11: ='Расчёт'!D4533 | W11: ='Расчёт'!D4534 | X11: ='Расчёт'!D4535 | Y11: ='Расчёт'!D4536 | Z11: ='Расчёт'!D4537 | AA11: ='Расчёт'!D4538 | AB11: ='Расчёт'!D4539 | AC11: ='Расчёт'!D4540 | AD11: ='Расчёт'!D4541 | AE11: ='Расчёт'!D4542 | AF11: ='Расчёт'!D4543 | AG11: ='Расчёт'!D4544 | AH11: ='Расчёт'!D4545 | AI11: ='Расчёт'!D4546 | AJ11: ='Расчёт'!D4547 | AK11: ='Расчёт'!D4548 | AL11: ='Расчёт'!D4549 | AM11: ='Расчёт'!D4550 | AN11: ='Расчёт'!D4551 | AO11: ='Расчёт'!D4552 | AP11: ='Расчёт'!D4553 | AQ11: ='Расчёт'!D4554 | AR11: ='Расчёт'!D4555 | AS11: ='Расчёт'!D4556 | AT11: ='Расчёт'!D4557 | AU11: ='Расчёт'!D4558 | AV11: ='Расчёт'!D4559 | AW11: ='Расчёт'!D4560 | AX11: ='Расчёт'!D4561 | AY11: ='Расчёт'!D4562 | AZ11: ='Расчёт'!D4563 | BA11: ='Расчёт'!D4564 | BB11: ='Расчёт'!D4565 | BD11: Иванов | BE11: =INDEX('Расчёт'!$D$4460:$D$4512,$BD$8)
A12: Сидоров | B12: ='Расчёт'!D4566 | C12: ='Расчёт'!D4567 | D12: ='Расчёт'!D4568 | E12: ='Расчёт'!D4569 | F12: ='Расчёт'!D4570 | G12: ='Расчёт'!D4571 | H12: ='Расчёт'!D4572 | I12: ='Расчёт'!D4573 | J12: ='Расчёт'!D4574 | K12: ='Расчёт'!D4575 | L12: ='Расчёт'!D4576 | M12: ='Расчёт'!D4577 | N12: ='Расчёт'!D4578 | O12: ='Расчёт'!D4579 | P12: ='Расчёт'!D4580 | Q12: ='Расчёт'!D4581 | R12: ='Расчёт'!D4582 | S12: ='Расчёт'!D4583 | T12: ='Расчёт'!D4584 | U12: ='Расчёт'!D4585 | V12: ='Расчёт'!D4586 | W12: ='Расчёт'!D4587 | X12: ='Расчёт'!D4588 | Y12: ='Расчёт'!D4589 | Z12: ='Расчёт'!D4590 | AA12: ='Расчёт'!D4591 | AB12: ='Расчёт'!D4592 | AC12: ='Расчёт'!D4593 | AD12: ='Расчёт'!D4594 | AE12: ='Расчёт'!D4595 | AF12: ='Расчёт'!D4596 | AG12: ='Расчёт'!D4597 | AH12: ='Расчёт'!D4598 | AI12: ='Расчёт'!D4599 | AJ12: ='Расчёт'!D4600 | AK12: ='Расчёт'!D4601 | AL12: ='Расчёт'!D4602 | AM12: ='Расчёт'!D4603 | AN12: ='Расчёт'!D4604 | AO12: ='Расчёт'!D4605 | AP12: ='Расчёт'!D4606 | AQ12: ='Расчёт'!D4607 | AR12: ='Расчёт'!D4608 | AS12: ='Расчёт'!D4609 | AT12: ='Расчёт'!D4610 | AU12: ='Расчёт'!D4611 | AV12: ='Расчёт'!D4612 | AW12: ='Расчёт'!D4613 | AX12: ='Расчёт'!D4614 | AY12: ='Расчёт'!D4615 | AZ12: ='Расчёт'!D4616 | BA12: ='Расчёт'!D4617 | BB12: ='Расчёт'!D4618 | BD12: Петрова | BE12: =INDEX('Расчёт'!$D$4513:$D$4565,$BD$8)
A13: Козлова | B13: ='Расчёт'!D4619 | C13: ='Расчёт'!D4620 | D13: ='Расчёт'!D4621 | E13: ='Расчёт'!D4622 | F13: ='Расчёт'!D4623 | G13: ='Расчёт'!D4624 | H13: ='Расчёт'!D4625 | I13: ='Расчёт'!D4626 | J13: ='Расчёт'!D4627 | K13: ='Расчёт'!D4628 | L13: ='Расчёт'!D4629 | M13: ='Расчёт'!D4630 | N13: ='Расчёт'!D4631 | O13: ='Расчёт'!D4632 | P13: ='Расчёт'!D4633 | Q13: ='Расчёт'!D4634 | R13: ='Расчёт'!D4635 | S13: ='Расчёт'!D4636 | T13: ='Расчёт'!D4637 | U13: ='Расчёт'!D4638 | V13: ='Расчёт'!D4639 | W13: ='Расчёт'!D4640 | X13: ='Расчёт'!D4641 | Y13: ='Расчёт'!D4642 | Z13: ='Расчёт'!D4643 | AA13: ='Расчёт'!D4644 | AB13: ='Расчёт'!D4645 | AC13: ='Расчёт'!D4646 | AD13: ='Расчёт'!D4647 | AE13: ='Расчёт'!D4648 | AF13: ='Расчёт'!D4649 | AG13: ='Расчёт'!D4650 | AH13: ='Расчёт'!D4651 | AI13: ='Расчёт'!D4652 | AJ13: ='Расчёт'!D4653 | AK13: ='Расчёт'!D4654 | AL13: ='Расчёт'!D4655 | AM13: ='Расчёт'!D4656 | AN13: ='Расчёт'!D4657 | AO13: ='Расчёт'!D4658 | AP13: ='Расчёт'!D4659 | AQ13: ='Расчёт'!D4660 | AR13: ='Расчёт'!D4661 | AS13: ='Расчёт'!D4662 | AT13: ='Расчёт'!D4663 | AU13: ='Расчёт'!D4664 | AV13: ='Расчёт'!D4665 | AW13: ='Расчёт'!D4666 | AX13: ='Расчёт'!D4667 | AY13: ='Расчёт'!D4668 | AZ13: ='Расчёт'!D4669 | BA13: ='Расчёт'!D4670 | BB13: ='Расчёт'!D4671 | BD13: Сидоров | BE13: =INDEX('Расчёт'!$D$4566:$D$4618,$BD$8)
A14: Новиков | B14: ='Расчёт'!D4672 | C14: ='Расчёт'!D4673 | D14: ='Расчёт'!D4674 | E14: ='Расчёт'!D4675 | F14: ='Расчёт'!D4676 | G14: ='Расчёт'!D4677 | H14: ='Расчёт'!D4678 | I14: ='Расчёт'!D4679 | J14: ='Расчёт'!D4680 | K14: ='Расчёт'!D4681 | L14: ='Расчёт'!D4682 | M14: ='Расчёт'!D4683 | N14: ='Расчёт'!D4684 | O14: ='Расчёт'!D4685 | P14: ='Расчёт'!D4686 | Q14: ='Расчёт'!D4687 | R14: ='Расчёт'!D4688 | S14: ='Расчёт'!D4689 | T14: ='Расчёт'!D4690 | U14: ='Расчёт'!D4691 | V14: ='Расчёт'!D4692 | W14: ='Расчёт'!D4693 | X14: ='Расчёт'!D4694 | Y14: ='Расчёт'!D4695 | Z14: ='Расчёт'!D4696 | AA14: ='Расчёт'!D4697 | AB14: ='Расчёт'!D4698 | AC14: ='Расчёт'!D4699 | AD14: ='Расчёт'!D4700 | AE14: ='Расчёт'!D4701 | AF14: ='Расчёт'!D4702 | AG14: ='Расчёт'!D4703 | AH14: ='Расчёт'!D4704 | AI14: ='Расчёт'!D4705 | AJ14: ='Расчёт'!D4706 | AK14: ='Расчёт'!D4707 | AL14: ='Расчёт'!D4708 | AM14: ='Расчёт'!D4709 | AN14: ='Расчёт'!D4710 | AO14: ='Расчёт'!D4711 | AP14: ='Расчёт'!D4712 | AQ14: ='Расчёт'!D4713 | AR14: ='Расчёт'!D4714 | AS14: ='Расчёт'!D4715 | AT14: ='Расчёт'!D4716 | AU14: ='Расчёт'!D4717 | AV14: ='Расчёт'!D4718 | AW14: ='Расчёт'!D4719 | AX14: ='Расчёт'!D4720 | AY14: ='Расчёт'!D4721 | AZ14: ='Расчёт'!D4722 | BA14: ='Расчёт'!D4723 | BB14: ='Расчёт'!D4724 | BD14: Козлова | BE14: =INDEX('Расчёт'!$D$4619:$D$4671,$BD$8)
A15: Морозова | B15: ='Расчёт'!D4725 | C15: ='Расчёт'!D4726 | D15: ='Расчёт'!D4727 | E15: ='Расчёт'!D4728 | F15: ='Расчёт'!D4729 | G15: ='Расчёт'!D4730 | H15: ='Расчёт'!D4731 | I15: ='Расчёт'!D4732 | J15: ='Расчёт'!D4733 | K15: ='Расчёт'!D4734 | L15: ='Расчёт'!D4735 | M15: ='Расчёт'!D4736 | N15: ='Расчёт'!D4737 | O15: ='Расчёт'!D4738 | P15: ='Расчёт'!D4739 | Q15: ='Расчёт'!D4740 | R15: ='Расчёт'!D4741 | S15: ='Расчёт'!D4742 | T15: ='Расчёт'!D4743 | U15: ='Расчёт'!D4744 | V15: ='Расчёт'!D4745 | W15: ='Расчёт'!D4746 | X15: ='Расчёт'!D4747 | Y15: ='Расчёт'!D4748 | Z15: ='Расчёт'!D4749 | AA15: ='Расчёт'!D4750 | AB15: ='Расчёт'!D4751 | AC15: ='Расчёт'!D4752 | AD15: ='Расчёт'!D4753 | AE15: ='Расчёт'!D4754 | AF15: ='Расчёт'!D4755 | AG15: ='Расчёт'!D4756 | AH15: ='Расчёт'!D4757 | AI15: ='Расчёт'!D4758 | AJ15: ='Расчёт'!D4759 | AK15: ='Расчёт'!D4760 | AL15: ='Расчёт'!D4761 | AM15: ='Расчёт'!D4762 | AN15: ='Расчёт'!D4763 | AO15: ='Расчёт'!D4764 | AP15: ='Расчёт'!D4765 | AQ15: ='Расчёт'!D4766 | AR15: ='Расчёт'!D4767 | AS15: ='Расчёт'!D4768 | AT15: ='Расчёт'!D4769 | AU15: ='Расчёт'!D4770 | AV15: ='Расчёт'!D4771 | AW15: ='Расчёт'!D4772 | AX15: ='Расчёт'!D4773 | AY15: ='Расчёт'!D4774 | AZ15: ='Расчёт'!D4775 | BA15: ='Расчёт'!D4776 | BB15: ='Расчёт'!D4777 | BD15: Новиков | BE15: =INDEX('Расчёт'!$D$4672:$D$4724,$BD$8)
A16: Волков | B16: ='Расчёт'!D4778 | C16: ='Расчёт'!D4779 | D16: ='Расчёт'!D4780 | E16: ='Расчёт'!D4781 | F16: ='Расчёт'!D4782 | G16: ='Расчёт'!D4783 | H16: ='Расчёт'!D4784 | I16: ='Расчёт'!D4785 | J16: ='Расчёт'!D4786 | K16: ='Расчёт'!D4787 | L16: ='Расчёт'!D4788 | M16: ='Расчёт'!D4789 | N16: ='Расчёт'!D4790 | O16: ='Расчёт'!D4791 | P16: ='Расчёт'!D4792 | Q16: ='Расчёт'!D4793 | R16: ='Расчёт'!D4794 | S16: ='Расчёт'!D4795 | T16: ='Расчёт'!D4796 | U16: ='Расчёт'!D4797 | V16: ='Расчёт'!D4798 | W16: ='Расчёт'!D4799 | X16: ='Расчёт'!D4800 | Y16: ='Расчёт'!D4801 | Z16: ='Расчёт'!D4802 | AA16: ='Расчёт'!D4803 | AB16: ='Расчёт'!D4804 | AC16: ='Расчёт'!D4805 | AD16: ='Расчёт'!D4806 | AE16: ='Расчёт'!D4807 | AF16: ='Расчёт'!D4808 | AG16: ='Расчёт'!D4809 | AH16: ='Расчёт'!D4810 | AI16: ='Расчёт'!D4811 | AJ16: ='Расчёт'!D4812 | AK16: ='Расчёт'!D4813 | AL16: ='Расчёт'!D4814 | AM16: ='Расчёт'!D4815 | AN16: ='Расчёт'!D4816 | AO16: ='Расчёт'!D4817 | AP16: ='Расчёт'!D4818 | AQ16: ='Расчёт'!D4819 | AR16: ='Расчёт'!D4820 | AS16: ='Расчёт'!D4821 | AT16: ='Расчёт'!D4822 | AU16: ='Расчёт'!D4823 | AV16: ='Расчёт'!D4824 | AW16: ='Расчёт'!D4825 | AX16: ='Расчёт'!D4826 | AY16: ='Расчёт'!D4827 | AZ16: ='Расчёт'!D4828 | BA16: ='Расчёт'!D4829 | BB16: ='Расчёт'!D4830 | BD16: Морозова | BE16: =INDEX('Расчёт'!$D$4725:$D$4777,$BD$8)
A17: Алексеева | B17: ='Расчёт'!D4831 | C17: ='Расчёт'!D4832 | D17: ='Расчёт'!D4833 | E17: ='Расчёт'!D4834 | F17: ='Расчёт'!D4835 | G17: ='Расчёт'!D4836 | H17: ='Расчёт'!D4837 | I17: ='Расчёт'!D4838 | J17: ='Расчёт'!D4839 | K17: ='Расчёт'!D4840 | L17: ='Расчёт'!D4841 | M17: ='Расчёт'!D4842 | N17: ='Расчёт'!D4843 | O17: ='Расчёт'!D4844 | P17: ='Расчёт'!D4845 | Q17: ='Расчёт'!D4846 | R17: ='Расчёт'!D4847 | S17: ='Расчёт'!D4848 | T17: ='Расчёт'!D4849 | U17: ='Расчёт'!D4850 | V17: ='Расчёт'!D4851 | W17: ='Расчёт'!D4852 | X17: ='Расчёт'!D4853 | Y17: ='Расчёт'!D4854 | Z17: ='Расчёт'!D4855 | AA17: ='Расчёт'!D4856 | AB17: ='Расчёт'!D4857 | AC17: ='Расчёт'!D4858 | AD17: ='Расчёт'!D4859 | AE17: ='Расчёт'!D4860 | AF17: ='Расчёт'!D4861 | AG17: ='Расчёт'!D4862 | AH17: ='Расчёт'!D4863 | AI17: ='Расчёт'!D4864 | AJ17: ='Расчёт'!D4865 | AK17: ='Расчёт'!D4866 | AL17: ='Расчёт'!D4867 | AM17: ='Расчёт'!D4868 | AN17: ='Расчёт'!D4869 | AO17: ='Расчёт'!D4870 | AP17: ='Расчёт'!D4871 | AQ17: ='Расчёт'!D4872 | AR17: ='Расчёт'!D4873 | AS17: ='Расчёт'!D4874 | AT17: ='Расчёт'!D4875 | AU17: ='Расчёт'!D4876 | AV17: ='Расчёт'!D4877 | AW17: ='Расчёт'!D4878 | AX17: ='Расчёт'!D4879 | AY17: ='Расчёт'!D4880 | AZ17: ='Расчёт'!D4881 | BA17: ='Расчёт'!D4882 | BB17: ='Расчёт'!D4883 | BD17: Волков | BE17: =INDEX('Расчёт'!$D$4778:$D$4830,$BD$8)
A18: Лебедев | B18: ='Расчёт'!D4884 | C18: ='Расчёт'!D4885 | D18: ='Расчёт'!D4886 | E18: ='Расчёт'!D4887 | F18: ='Расчёт'!D4888 | G18: ='Расчёт'!D4889 | H18: ='Расчёт'!D4890 | I18: ='Расчёт'!D4891 | J18: ='Расчёт'!D4892 | K18: ='Расчёт'!D4893 | L18: ='Расчёт'!D4894 | M18: ='Расчёт'!D4895 | N18: ='Расчёт'!D4896 | O18: ='Расчёт'!D4897 | P18: ='Расчёт'!D4898 | Q18: ='Расчёт'!D4899 | R18: ='Расчёт'!D4900 | S18: ='Расчёт'!D4901 | T18: ='Расчёт'!D4902 | U18: ='Расчёт'!D4903 | V18: ='Расчёт'!D4904 | W18: ='Расчёт'!D4905 | X18: ='Расчёт'!D4906 | Y18: ='Расчёт'!D4907 | Z18: ='Расчёт'!D4908 | AA18: ='Расчёт'!D4909 | AB18: ='Расчёт'!D4910 | AC18: ='Расчёт'!D4911 | AD18: ='Расчёт'!D4912 | AE18: ='Расчёт'!D4913 | AF18: ='Расчёт'!D4914 | AG18: ='Расчёт'!D4915 | AH18: ='Расчёт'!D4916 | AI18: ='Расчёт'!D4917 | AJ18: ='Расчёт'!D4918 | AK18: ='Расчёт'!D4919 | AL18: ='Расчёт'!D4920 | AM18: ='Расчёт'!D4921 | AN18: ='Расчёт'!D4922 | AO18: ='Расчёт'!D4923 | AP18: ='Расчёт'!D4924 | AQ18: ='Расчёт'!D4925 | AR18: ='Расчёт'!D4926 | AS18: ='Расчёт'!D4927 | AT18: ='Расчёт'!D4928 | AU18: ='Расчёт'!D4929 | AV18: ='Расчёт'!D4930 | AW18: ='Расчёт'!D4931 | AX18: ='Расчёт'!D4932 | AY18: ='Расчёт'!D4933 | AZ18: ='Расчёт'!D4934 | BA18: ='Расчёт'!D4935 | BB18: ='Расчёт'!D4936 | BD18: Алексеева | BE18: =INDEX('Расчёт'!$D$4831:$D$4883,$BD$8)
A19: Семенова | B19: ='Расчёт'!D4937 | C19: ='Расчёт'!D4938 | D19: ='Расчёт'!D4939 | E19: ='Расчёт'!D4940 | F19: ='Расчёт'!D4941 | G19: ='Расчёт'!D4942 | H19: ='Расчёт'!D4943 | I19: ='Расчёт'!D4944 | J19: ='Расчёт'!D4945 | K19: ='Расчёт'!D4946 | L19: ='Расчёт'!D4947 | M19: ='Расчёт'!D4948 | N19: ='Расчёт'!D4949 | O19: ='Расчёт'!D4950 | P19: ='Расчёт'!D4951 | Q19: ='Расчёт'!D4952 | R19: ='Расчёт'!D4953 | S19: ='Расчёт'!D4954 | T19: ='Расчёт'!D4955 | U19: ='Расчёт'!D4956 | V19: ='Расчёт'!D4957 | W19: ='Расчёт'!D4958 | X19: ='Расчёт'!D4959 | Y19: ='Расчёт'!D4960 | Z19: ='Расчёт'!D4961 | AA19: ='Расчёт'!D4962 | AB19: ='Расчёт'!D4963 | AC19: ='Расчёт'!D4964 | AD19: ='Расчёт'!D4965 | AE19: ='Расчёт'!D4966 | AF19: ='Расчёт'!D4967 | AG19: ='Расчёт'!D4968 | AH19: ='Расчёт'!D4969 | AI19: ='Расчёт'!D4970 | AJ19: ='Расчёт'!D4971 | AK19: ='Расчёт'!D4972 | AL19: ='Расчёт'!D4973 | AM19: ='Расчёт'!D4974 | AN19: ='Расчёт'!D4975 | AO19: ='Расчёт'!D4976 | AP19: ='Расчёт'!D4977 | AQ19: ='Расчёт'!D4978 | AR19: ='Расчёт'!D4979 | AS19: ='Расчёт'!D4980 | AT19: ='Расчёт'!D4981 | AU19: ='Расчёт'!D4982 | AV19: ='Расчёт'!D4983 | AW19: ='Расчёт'!D4984 | AX19: ='Расчёт'!D4985 | AY19: ='Расчёт'!D4986 | AZ19: ='Расчёт'!D4987 | BA19: ='Расчёт'!D4988 | BB19: ='Расчёт'!D4989 | BD19: Лебедев | BE19: =INDEX('Расчёт'!$D$4884:$D$4936,$BD$8)
A20: Егоров | B20: ='Расчёт'!D4990 | C20: ='Расчёт'!D4991 | D20: ='Расчёт'!D4992 | E20: ='Расчёт'!D4993 | F20: ='Расчёт'!D4994 | G20: ='Расчёт'!D4995 | H20: ='Расчёт'!D4996 | I20: ='Расчёт'!D4997 | J20: ='Расчёт'!D4998 | K20: ='Расчёт'!D4999 | L20: ='Расчёт'!D5000 | M20: ='Расчёт'!D5001 | N20: ='Расчёт'!D5002 | O20: ='Расчёт'!D5003 | P20: ='Расчёт'!D5004 | Q20: ='Расчёт'!D5005 | R20: ='Расчёт'!D5006 | S20: ='Расчёт'!D5007 | T20: ='Расчёт'!D5008 | U20: ='Расчёт'!D5009 | V20: ='Расчёт'!D5010 | W20: ='Расчёт'!D5011 | X20: ='Расчёт'!D5012 | Y20: ='Расчёт'!D5013 | Z20: ='Расчёт'!D5014 | AA20: ='Расчёт'!D5015 | AB20: ='Расчёт'!D5016 | AC20: ='Расчёт'!D5017 | AD20: ='Расчёт'!D5018 | AE20: ='Расчёт'!D5019 | AF20: ='Расчёт'!D5020 | AG20: ='Расчёт'!D5021 | AH20: ='Расчёт'!D5022 | AI20: ='Расчёт'!D5023 | AJ20: ='Расчёт'!D5024 | AK20: ='Расчёт'!D5025 | AL20: ='Расчёт'!D5026 | AM20: ='Расчёт'!D5027 | AN20: ='Расчёт'!D5028 | AO20: ='Расчёт'!D5029 | AP20: ='Расчёт'!D5030 | AQ20: ='Расчёт'!D5031 | AR20: ='Расчёт'!D5032 | AS20: ='Расчёт'!D5033 | AT20: ='Расчёт'!D5034 | AU20: ='Расчёт'!D5035 | AV20: ='Расчёт'!D5036 | AW20: ='Расчёт'!D5037 | AX20: ='Расчёт'!D5038 | AY20: ='Расчёт'!D5039 | AZ20: ='Расчёт'!D5040 | BA20: ='Расчёт'!D5041 | BB20: ='Расчёт'!D5042 | BD20: Семенова | BE20: =INDEX('Расчёт'!$D$4937:$D$4989,$BD$8)
A21: Павлова | B21: ='Расчёт'!D5043 | C21: ='Расчёт'!D5044 | D21: ='Расчёт'!D5045 | E21: ='Расчёт'!D5046 | F21: ='Расчёт'!D5047 | G21: ='Расчёт'!D5048 | H21: ='Расчёт'!D5049 | I21: ='Расчёт'!D5050 | J21: ='Расчёт'!D5051 | K21: ='Расчёт'!D5052 | L21: ='Расчёт'!D5053 | M21: ='Расчёт'!D5054 | N21: ='Расчёт'!D5055 | O21: ='Расчёт'!D5056 | P21: ='Расчёт'!D5057 | Q21: ='Расчёт'!D5058 | R21: ='Расчёт'!D5059 | S21: ='Расчёт'!D5060 | T21: ='Расчёт'!D5061 | U21: ='Расчёт'!D5062 | V21: ='Расчёт'!D5063 | W21: ='Расчёт'!D5064 | X21: ='Расчёт'!D5065 | Y21: ='Расчёт'!D5066 | Z21: ='Расчёт'!D5067 | AA21: ='Расчёт'!D5068 | AB21: ='Расчёт'!D5069 | AC21: ='Расчёт'!D5070 | AD21: ='Расчёт'!D5071 | AE21: ='Расчёт'!D5072 | AF21: ='Расчёт'!D5073 | AG21: ='Расчёт'!D5074 | AH21: ='Расчёт'!D5075 | AI21: ='Расчёт'!D5076 | AJ21: ='Расчёт'!D5077 | AK21: ='Расчёт'!D5078 | AL21: ='Расчёт'!D5079 | AM21: ='Расчёт'!D5080 | AN21: ='Расчёт'!D5081 | AO21: ='Расчёт'!D5082 | AP21: ='Расчёт'!D5083 | AQ21: ='Расчёт'!D5084 | AR21: ='Расчёт'!D5085 | AS21: ='Расчёт'!D5086 | AT21: ='Расчёт'!D5087 | AU21: ='Расчёт'!D5088 | AV21: ='Расчёт'!D5089 | AW21: ='Расчёт'!D5090 | AX21: ='Расчёт'!D5091 | AY21: ='Расчёт'!D5092 | AZ21: ='Расчёт'!D5093 | BA21: ='Расчёт'!D5094 | BB21: ='Расчёт'!D5095 | BD21: Егоров | BE21: =INDEX('Расчёт'!$D$4990:$D$5042,$BD$8)
A22: ИТОГО | B22: =SUM(B10:B21) | C22: =SUM(C10:C21) | D22: =SUM(D10:D21) | E22: =SUM(E10:E21) | F22: =SUM(F10:F21) | G22: =SUM(G10:G21) | H22: =SUM(H10:H21) | I22: =SUM(I10:I21) | ... BB22: =SUM(BB10:BB21) | BD22: Павлова | BE22: =INDEX('Расчёт'!$D$5043:$D$5095,$BD$8)

Sheet Планы менеджеров
A1: МЕСЯЧНЫЕ ПЛАНЫ МЕНЕДЖЕРОВ
A2: Редактируйте жёлтые ячейки: план на календарный месяц для каждого менеджера. Распределение по фин. неделям и стыки месяцев считаются автоматически.
A4: Менеджер | B4: Январь 2026 | C4: Февраль 2026 | D4: Март 2026 | E4: Апрель 2026 | F4: Май 2026 | G4: Июнь 2026 | H4: Июль 2026 | I4: Август 2026 | J4: Сентябрь 2026 | K4: Октябрь 2026 | L4: Ноябрь 2026 | M4: Декабрь 2026
A5: Иванов | B5: 5000000 | C5: 4800000 | D5: 5200000 | E5: 5500000 | F5: 5300000 | G5: 6000000 | H5: 6200000 | I5: 6000000 | J5: 5800000 | K5: 6500000 | L5: 7000000 | M5: 8000000
A6: Петрова | B6: 5000000 | C6: 4800000 | D6: 5200000 | E6: 5500000 | F6: 5300000 | G6: 6000000 | H6: 6200000 | I6: 6000000 | J6: 5800000 | K6: 6500000 | L6: 7000000 | M6: 8000000
A7: Сидоров | B7: 5000000 | C7: 4800000 | D7: 5200000 | E7: 5500000 | F7: 5300000 | G7: 6000000 | H7: 6200000 | I7: 6000000 | J7: 5800000 | K7: 6500000 | L7: 7000000 | M7: 8000000
A8: Козлова | B8: 5000000 | C8: 4800000 | D8: 5200000 | E8: 5500000 | F8: 5300000 | G8: 6000000 | H8: 6200000 | I8: 6000000 | J8: 5800000 | K8: 6500000 | L8: 7000000 | M8: 8000000
A9: Новиков | B9: 5000000 | C9: 4800000 | D9: 5200000 | E9: 5500000 | F9: 5300000 | G9: 6000000 | H9: 6200000 | I9: 6000000 | J9: 5800000 | K9: 6500000 | L9: 7000000 | M9: 8000000
A10: Морозова | B10: 5000000 | C10: 4800000 | D10: 5200000 | E10: 5500000 | F10: 5300000 | G10: 6000000 | H10: 6200000 | I10: 6000000 | J10: 5800000 | K10: 6500000 | L10: 7000000 | M10: 8000000
A11: Волков | B11: 5000000 | C11: 4800000 | D11: 5200000 | E11: 5500000 | F11: 5300000 | G11: 6000000 | H11: 6200000 | I11: 6000000 | J11: 5800000 | K11: 6500000 | L11: 7000000 | M11: 8000000
A12: Алексеева | B12: 5000000 | C12: 4800000 | D12: 5200000 | E12: 5500000 | F12: 5300000 | G12: 6000000 | H12: 6200000 | I12: 6000000 | J12: 5800000 | K12: 6500000 | L12: 7000000 | M12: 8000000
A13: Лебедев | B13: 5000000 | C13: 4800000 | D13: 5200000 | E13: 5500000 | F13: 5300000 | G13: 6000000 | H13: 6200000 | I13: 6000000 | J13: 5800000 | K13: 6500000 | L13: 7000000 | M13: 8000000
A14: Семенова | B14: 5000000 | C14: 4800000 | D14: 5200000 | E14: 5500000 | F14: 5300000 | G14: 6000000 | H14: 6200000 | I14: 6000000 | J14: 5800000 | K14: 6500000 | L14: 7000000 | M14: 8000000
A15: Егоров | B15: 5000000 | C15: 4800000 | D15: 5200000 | E15: 5500000 | F15: 5300000 | G15: 6000000 | H15: 6200000 | I15: 6000000 | J15: 5800000 | K15: 6500000 | L15: 7000000 | M15: 8000000
A16: Павлова | B16: 5000000 | C16: 4800000 | D16: 5200000 | E16: 5500000 | F16: 5300000 | G16: 6000000 | H16: 6200000 | I16: 6000000 | J16: 5800000 | K16: 6500000 | L16: 7000000 | M16: 8000000
A17: ИТОГО | B17: =SUM(B5:B16) | C17: =SUM(C5:C16) | D17: =SUM(D5:D16) | E17: =SUM(E5:E16) | F17: =SUM(F5:F16) | G17: =SUM(G5:G16) | H17: =SUM(H5:H16) | I17: =SUM(I5:I16) | ... M17: =SUM(M5:M16)

Sheet Рабочие дни
A1: РАБОЧИЕ ДНИ И ФИНАНСОВЫЕ НЕДЕЛИ
A2: ЖЁЛТЫЕ ячейки — ввод вручную. Остальное считается формулами.
A4: Месяц | B4: Рабочих дней в месяце (ВАША СТРОКА ВВОДА) | C4: Недель в месяце
A5: Январь 2026 | B5: =SUMPRODUCT((Кал_Месяц=1)*(Кал_Раб=1)) | C5: 5 | E5: По умолчанию в «Календаре» рабочими считаются пн–пт. Праздники вычитайте из числа рабочих дней вручную.
A6: Февраль 2026 | B6: =SUMPRODUCT((Кал_Месяц=2)*(Кал_Раб=1)) | C6: 4
A7: Март 2026 | B7: =SUMPRODUCT((Кал_Месяц=3)*(Кал_Раб=1)) | C7: 4
A8: Апрель 2026 | B8: =SUMPRODUCT((Кал_Месяц=4)*(Кал_Раб=1)) | C8: 5
A9: Май 2026 | B9: =SUMPRODUCT((Кал_Месяц=5)*(Кал_Раб=1)) | C9: 4
A10: Июнь 2026 | B10: =SUMPRODUCT((Кал_Месяц=6)*(Кал_Раб=1)) | C10: 4
A11: Июль 2026 | B11: =SUMPRODUCT((Кал_Месяц=7)*(Кал_Раб=1)) | C11: 5
A12: Август 2026 | B12: =SUMPRODUCT((Кал_Месяц=8)*(Кал_Раб=1)) | C12: 4
A13: Сентябрь 2026 | B13: =SUMPRODUCT((Кал_Месяц=9)*(Кал_Раб=1)) | C13: 4
A14: Октябрь 2026 | B14: =SUMPRODUCT((Кал_Месяц=10)*(Кал_Раб=1)) | C14: 5
A15: Ноябрь 2026 | B15: =SUMPRODUCT((Кал_Месяц=11)*(Кал_Раб=1)) | C15: 4
A16: Декабрь 2026 | B16: =SUMPRODUCT((Кал_Месяц=12)*(Кал_Раб=1)) | C16: 5
A18: Границы финансовых недель (четверг — среда)
A19: № фин. недели | B19: Начало (чт) | C19: Конец (ср) | D19: Месяц открытия | E19: Рабочих дней в неделе
A20: 1 | B20: 46023 | C20: 46029 | D20: Январь 2026 | E20: =SUMPRODUCT((Кал_Даты>=$B20)*(Кал_Даты<=$C20)*(Кал_Раб=1))
A21: 2 | B21: 46030 | C21: 46036 | D21: Январь 2026 | E21: =SUMPRODUCT((Кал_Даты>=$B21)*(Кал_Даты<=$C21)*(Кал_Раб=1))
A22: 3 | B22: 46037 | C22: 46043 | D22: Январь 2026 | E22: =SUMPRODUCT((Кал_Даты>=$B22)*(Кал_Даты<=$C22)*(Кал_Раб=1))
A23: 4 | B23: 46044 | C23: 46050 | D23: Январь 2026 | E23: =SUMPRODUCT((Кал_Даты>=$B23)*(Кал_Даты<=$C23)*(Кал_Раб=1))
A24: 5 | B24: 46051 | C24: 46057 | D24: Январь 2026 | E24: =SUMPRODUCT((Кал_Даты>=$B24)*(Кал_Даты<=$C24)*(Кал_Раб=1))
A25: 6 | B25: 46058 | C25: 46064 | D25: Февраль 2026 | E25: =SUMPRODUCT((Кал_Даты>=$B25)*(Кал_Даты<=$C25)*(Кал_Раб=1))
A26: 7 | B26: 46065 | C26: 46071 | D26: Февраль 2026 | E26: =SUMPRODUCT((Кал_Даты>=$B26)*(Кал_Даты<=$C26)*(Кал_Раб=1))
A27: 8 | B27: 46072 | C27: 46078 | D27: Февраль 2026 | E27: =SUMPRODUCT((Кал_Даты>=$B27)*(Кал_Даты<=$C27)*(Кал_Раб=1))
A28: 9 | B28: 46079 | C28: 46085 | D28: Февраль 2026 | E28: =SUMPRODUCT((Кал_Даты>=$B28)*(Кал_Даты<=$C28)*(Кал_Раб=1))
A29: 10 | B29: 46086 | C29: 46092 | D29: Март 2026 | E29: =SUMPRODUCT((Кал_Даты>=$B29)*(Кал_Даты<=$C29)*(Кал_Раб=1))
A30: 11 | B30: 46093 | C30: 46099 | D30: Март 2026 | E30: =SUMPRODUCT((Кал_Даты>=$B30)*(Кал_Даты<=$C30)*(Кал_Раб=1))
A31: 12 | B31: 46100 | C31: 46106 | D31: Март 2026 | E31: =SUMPRODUCT((Кал_Даты>=$B31)*(Кал_Даты<=$C31)*(Кал_Раб=1))
... A72: 53 | B72: 46387 | C72: 46393 | D72: Декабрь 2026 | E72: =SUMPRODUCT((Кал_Даты>=$B72)*(Кал_Даты<=$C72)*(Кал_Раб=1))

Sheet Календарь
A1: Дата | B1: Месяц № | C1: День недели | D1: Рабочий день (1/0)
A2: 46023 | B2: 1 | C2: Четверг | D2: 1
A3: 46024 | B3: 1 | C3: Пятница | D3: 1
A4: 46025 | B4: 1 | C4: Суббота | D4: 0
A5: 46026 | B5: 1 | C5: Воскресенье | D5: 0
A6: 46027 | B6: 1 | C6: Понедельник | D6: 1
A7: 46028 | B7: 1 | C7: Вторник | D7: 1
A8: 46029 | B8: 1 | C8: Среда | D8: 1
A9: 46030 | B9: 1 | C9: Четверг | D9: 1
A10: 46031 | B10: 1 | C10: Пятница | D10: 1
A11: 46032 | B11: 1 | C11: Суббота | D11: 0
A12: 46033 | B12: 1 | C12: Воскресенье | D12: 0
A13: 46034 | B13: 1 | C13: Понедельник | D13: 1
... A366: 46387 | B366: 12 | C366: Четверг | D366: 1

Sheet Расчёт
A1: СЛУЖЕБНЫЙ РАСЧЁТ (не редактировать)
A2: Блок 1: план дня = план месяца / число рабочих дней месяца (выходные = 0). Блок 2: план недели = сумма планов её дней; дни недели, попавшие на разные месяцы, считаются по плану каждого месяца (стык месяцев учтён).
A4: Менеджер | B4: Строка плана | C4: Дата | D4: Месяц даты | E4: Рабочий? | F4: № фин. недели | G4: План на день
A5: Иванов | B5: 5 | C5: ='Календарь'!A2 | D5: =MONTH(C5) | E5: ='Календарь'!D2 | F5: =INT((C5-Нед_Начало)/7)+1 | G5: =IF(E5=0,0,INDEX('Планы менеджеров'!$B$5:$M$16,B5,D5)/INDEX(Мес_Раб,D5))
A6: Иванов | B6: 5 | C6: ='Календарь'!A3 | D6: =MONTH(C6) | E6: ='Календарь'!D3 | F6: =INT((C6-Нед_Начало)/7)+1 | G6: =IF(E6=0,0,INDEX('Планы менеджеров'!$B$5:$M$16,B6,D6)/INDEX(Мес_Раб,D6))
A7: Иванов | B7: 5 | C7: ='Календарь'!A4 | D7: =MONTH(C7) | E7: ='Календарь'!D4 | F7: =INT((C7-Нед_Начало)/7)+1 | G7: =IF(E7=0,0,INDEX('Планы менеджеров'!$B$5:$M$16,B7,D7)/INDEX(Мес_Раб,D7))
A8: Иванов | B8: 5 | C8: ='Календарь'!A5 | D8: =MONTH(C8) | E8: ='Календарь'!D5 | F8: =INT((C8-Нед_Начало)/7)+1 | G8: =IF(E8=0,0,INDEX('Планы менеджеров'!$B$5:$M$16,B8,D8)/INDEX(Мес_Раб,D8))
A9: Иванов | B9: 5 | C9: ='Календарь'!A6 | D9: =MONTH(C9) | E9: ='Календарь'!D6 | F9: =INT((C9-Нед_Начало)/7)+1 | G9: =IF(E9=0,0,INDEX('Планы менеджеров'!$B$5:$M$16,B9,D9)/INDEX(Мес_Раб,D9))
A10: Иванов | B10: 5 | C10: ='Календарь'!A7 | D10: =MONTH(C10) | E10: ='Календарь'!D7 | F10: =INT((C10-Нед_Начало)/7)+1 | G10: =IF(E10=0,0,INDEX('Планы менеджеров'!$B$5:$M$16,B10,D10)/INDEX(Мес_Раб,D10))
A11: Иванов | B11: 5 | C11: ='Календарь'!A8 | D11: =MONTH(C11) | E11: ='Календарь'!D8 | F11: =INT((C11-Нед_Начало)/7)+1 | G11: =IF(E11=0,0,INDEX('Планы менеджеров'!$B$5:$M$16,B11,D11)/INDEX(Мес_Раб,D11))
A12: Иванов | B12: 5 | C12: ='Календарь'!A9 | D12: =MONTH(C12) | E12: ='Календарь'!D9 | F12: =INT((C12-Нед_Начало)/7)+1 | G12: =IF(E12=0,0,INDEX('Планы менеджеров'!$B$5:$M$16,B12,D12)/INDEX(Мес_Раб,D12))
A13: Иванов | B13: 5 | C13: ='Календарь'!A10 | D13: =MONTH(C13) | E13: ='Календарь'!D10 | F13: =INT((C13-Нед_Начало)/7)+1 | G13: =IF(E13=0,0,INDEX('Планы менеджеров'!$B$5:$M$16,B13,D13)/INDEX(Мес_Раб,D13))
A14: Иванов | B14: 5 | C14: ='Календарь'!A11 | D14: =MONTH(C14) | E14: ='Календарь'!D11 | F14: =INT((C14-Нед_Начало)/7)+1 | G14: =IF(E14=0,0,INDEX('Планы менеджеров'!$B$5:$M$16,B14,D14)/INDEX(Мес_Раб,D14))
A15: Иванов | B15: 5 | C15: ='Календарь'!A12 | D15: =MONTH(C15) | E15: ='Календарь'!D12 | F15: =INT((C15-Нед_Начало)/7)+1 | G15: =IF(E15=0,0,INDEX('Планы менеджеров'!$B$5:$M$16,B15,D15)/INDEX(Мес_Раб,D15))
A16: Иванов | B16: 5 | C16: ='Календарь'!A13 | D16: =MONTH(C16) | E16: ='Календарь'!D13 | F16: =INT((C16-Нед_Начало)/7)+1 | G16: =IF(E16=0,0,INDEX('Планы менеджеров'!$B$5:$M$16,B16,D16)/INDEX(Мес_Раб,D16))
... A375: Иванов | B375: 5 | C375: ='Календарь'!A372 | D375: =MONTH(C375) | E375: ='Календарь'!D372 | F375: =INT((C375-Нед_Начало)/7)+1 | G375: =IF(E375=0,0,INDEX('Планы менеджеров'!$B$5:$M$16,B375,D375)/INDEX(Мес_Раб,D375))
A376: Петрова | B376: 6 | C376: ='Календарь'!A2 | D376: =MONTH(C376) | E376: ='Календарь'!D2 | F376: =INT((C376-Нед_Начало)/7)+1 | G376: =IF(E376=0,0,INDEX('Планы менеджеров'!$B$5:$M$16,B376,D376)/INDEX(Мес_Раб,D376))
A377: Петрова | B377: 6 | C377: ='Календарь'!A3 | D377: =MONTH(C377) | E377: ='Календарь'!D3 | F377: =INT((C377-Нед_Начало)/7)+1 | G377: =IF(E377=0,0,INDEX('Планы менеджеров'!$B$5:$M$16,B377,D377)/INDEX(Мес_Раб,D377))
A378: Петрова | B378: 6 | C378: ='Календарь'!A4 | D378: =MONTH(C378) | E378: ='Календарь'!D4 | F378: =INT((C378-Нед_Начало)/7)+1 | G378: =IF(E378=0,0,INDEX('Планы менеджеров'!$B$5:$M$16,B378,D378)/INDEX(Мес_Раб,D378))
A379: Петрова | B379: 6 | C379: ='Календарь'!A5 | D379: =MONTH(C379) | E379: ='Календарь'!D5 | F379: =INT((C379-Нед_Начало)/7)+1 | G379: =IF(E379=0,0,INDEX('Планы менеджеров'!$B$5:$M$16,B379,D379)/INDEX(Мес_Раб,D379))
A380: Петрова | B380: 6 | C380: ='Календарь'!A6 | D380: =MONTH(C380) | E380: ='Календарь'!D6 | F380: =INT((C380-Нед_Начало)/7)+1 | G380: =IF(E380=0,0,INDEX('Планы менеджеров'!$B$5:$M$16,B380,D380)/INDEX(Мес_Раб,D380))
A381: Петрова | B381: 6 | C381: ='Календарь'!A7 | D381: =MONTH(C381) | E381: ='Календарь'!D7 | F381: =INT((C381-Нед_Начало)/7)+1 | G381: =IF(E381=0,0,INDEX('Планы менеджеров'!$B$5:$M$16,B381,D381)/INDEX(Мес_Раб,D381))
A382: Петрова | B382: 6 | C382: ='Календарь'!A8 | D382: =MONTH(C382) | E382: ='Календарь'!D8 | F382: =INT((C382-Нед_Начало)/7)+1 | G382: =IF(E382=0,0,INDEX('Планы менеджеров'!$B$5:$M$16,B382,D382)/INDEX(Мес_Раб,D382))
A383: Петрова | B383: 6 | C383: ='Календарь'!A9 | D383: =MONTH(C383) | E383: ='Календарь'!D9 | F383: =INT((C383-Нед_Начало)/7)+1 | G383: =IF(E383=0,0,INDEX('Планы менеджеров'!$B$5:$M$16,B383,D383)/INDEX(Мес_Раб,D383))
A384: Петрова | B384: 6 | C384: ='Календарь'!A10 | D384: =MONTH(C384) | E384: ='Календарь'!D10 | F384: =INT((C384-Нед_Начало)/7)+1 | G384: =IF(E384=0,0,INDEX('Планы менеджеров'!$B$5:$M$16,B384,D384)/INDEX(Мес_Раб,D384))
A385: Петрова | B385: 6 | C385: ='Календарь'!A11 | D385: =MONTH(C385) | E385: ='Календарь'!D11 | F385: =INT((C385-Нед_Начало)/7)+1 | G385: =IF(E385=0,0,INDEX('Планы менеджеров'!$B$5:$M$16,B385,D385)/INDEX(Мес_Раб,D385))
A386: Петрова | B386: 6 | C386: ='Календарь'!A12 | D386: =MONTH(C386) | E386: ='Календарь'!D12 | F386: =INT((C386-Нед_Начало)/7)+1 | G386: =IF(E386=0,0,INDEX('Планы менеджеров'!$B$5:$M$16,B386,D386)/INDEX(Мес_Раб,D386))
A387: Петрова | B387: 6 | C387: ='Календарь'!A13 | D387: =MONTH(C387) | E387: ='Календарь'!D13 | F387: =INT((C387-Нед_Начало)/7)+1 | G387: =IF(E387=0,0,INDEX('Планы менеджеров'!$B$5:$M$16,B387,D387)/INDEX(Мес_Раб,D387))
... A746: Петрова | B746: 6 | C746: ='Календарь'!A372 | D746: =MONTH(C746) | E746: ='Календарь'!D372 | F746: =INT((C746-Нед_Начало)/7)+1 | G746: =IF(E746=0,0,INDEX('Планы менеджеров'!$B$5:$M$16,B746,D746)/INDEX(Мес_Раб,D746))
A747: Сидоров | B747: 7 | C747: ='Календарь'!A2 | D747: =MONTH(C747) | E747: ='Календарь'!D2 | F747: =INT((C747-Нед_Начало)/7)+1 | G747: =IF(E747=0,0,INDEX('Планы менеджеров'!$B$5:$M$16,B747,D747)/INDEX(Мес_Раб,D747))
A748: Сидоров | B748: 7 | C748: ='Календарь'!A3 | D748: =MONTH(C748) | E748: ='Календарь'!D3 | F748: =INT((C748-Нед_Начало)/7)+1 | G748: =IF(E748=0,0,INDEX('Планы менеджеров'!$B$5:$M$16,B748,D748)/INDEX(Мес_Раб,D748))
A749: Сидоров | B749: 7 | C749: ='Календарь'!A4 | D749: =MONTH(C749) | E749: ='Календарь'!D4 | F749: =INT((C749-Нед_Начало)/7)+1 | G749: =IF(E749=0,0,INDEX('Планы менеджеров'!$B$5:$M$16,B749,D749)/INDEX(Мес_Раб,D749))
A750: Сидоров | B750: 7 | C750: ='Календарь'!A5 | D750: =MONTH(C750) | E750: ='Календарь'!D5 | F750: =INT((C750-Нед_Начало)/7)+1 | G750: =IF(E750=0,0,INDEX('Планы менеджеров'!$B$5:$M$16,B750,D750)/INDEX(Мес_Раб,D750))
A751: Сидоров | B751: 7 | C751: ='Календарь'!A6 | D751: =MONTH(C751) | E751: ='Календарь'!D6 | F751: =INT((C751-Нед_Начало)/7)+1 | G751: =IF(E751=0,0,INDEX('Планы менеджеров'!$B$5:$M$16,B751,D751)/INDEX(Мес_Раб,D751))
A752: Сидоров | B752: 7 | C752: ='Календарь'!A7 | D752: =MONTH(C752) | E752: ='Календарь'!D7 | F752: =INT((C752-Нед_Начало)/7)+1 | G752: =IF(E752=0,0,INDEX('Планы менеджеров'!$B$5:$M$16,B752,D752)/INDEX(Мес_Раб,D752))
A753: Сидоров | B753: 7 | C753: ='Календарь'!A8 | D753: =MONTH(C753) | E753: ='Календарь'!D8 | F753: =INT((C753-Нед_Начало)/7)+1 | G753: =IF(E753=0,0,INDEX('Планы менеджеров'!$B$5:$M$16,B753,D753)/INDEX(Мес_Раб,D753))
A754: Сидоров | B754: 7 | C754: ='Календарь'!A9 | D754: =MONTH(C754) | E754: ='Календарь'!D9 | F754: =INT((C754-Нед_Начало)/7)+1 | G754: =IF(E754=0,0,INDEX('Планы менеджеров'!$B$5:$M$16,B754,D754)/INDEX(Мес_Раб,D754))
A755: Сидоров | B755: 7 | C755: ='Календарь'!A10 | D755: =MONTH(C755) | E755: ='Календарь'!D10 | F755: =INT((C755-Нед_Начало)/7)+1 | G755: =IF(E755=0,0,INDEX('Планы менеджеров'!$B$5:$M$16,B755,D755)/INDEX(Мес_Раб,D755))
A756: Сидоров | B756: 7 | C756: ='Календарь'!A11 | D756: =MONTH(C756) | E756: ='Календарь'!D11 | F756: =INT((C756-Нед_Начало)/7)+1 | G756: =IF(E756=0,0,INDEX('Планы менеджеров'!$B$5:$M$16,B756,D756)/INDEX(Мес_Раб,D756))
A757: Сидоров | B757: 7 | C757: ='Календарь'!A12 | D757: =MONTH(C757) | E757: ='Календарь'!D12 | F757: =INT((C757-Нед_Начало)/7)+1 | G757: =IF(E757=0,0,INDEX('Планы менеджеров'!$B$5:$M$16,B757,D757)/INDEX(Мес_Раб,D757))
...
